---
title:  "Go 19. 에러 핸들링"

categories:
  - go

toc: true
toc_sticky: true
 
date: 2021-10-03
---
# 1\. 에러 반환

-   함수에서 에러를 반환, 호출자에게 에러처리 위임
    
-   사용자 에러 반환
    
    -   에러함수 : `fmt.Errorf(), errors.New()`

```go
  func Function() error {
      return fmt.Errorf("...")
  }

  func main() {
      err := Function()
      fmt.Printf("%v", err)
  }

  // ---------------------------

  func Function() error {
      return errors.New("...")
  }

  func main() {
      err := Function()
      fmt.Printf("%v", err)
  }
```

# 2\. 에러 타입

```go
type error interface {
  Error() string
}
```

```go
package main

import (
      "fmt"
)

type PasswordError struct {
      Len        int
      RequireLen int
}

func (err PasswordError) Error() string {
      return "password is short"
}

func RegisterAccount(name, password string) error {
      if len(password) < 8 {
          return PasswordError{len(password), 8}
      }

      return nil
}

func main() {
      err := RegisterAccount("myId", "myPw")

      fmt.Printf("%v\n", err)
      if err != nil {
          if errInfo, ok := err.(PasswordError); ok {
              fmt.Printf("%v len: %d\n", errInfo, errInfo.Len)
          } else {
              fmt.Println("success")
          }
      }
}

// 출력
// password is short
// password is short len: 4
```

# 3\. 에러 랩핑 (Wrapping)

-   `fmt.Errorf()` 의 `%w` 포맷터로 에러 랩핑 가능
    
-   `errors.Is(), As()`
    
-   Depth가 깊어질 때, 어디서 정확히 에러가 났는지 알려줌
    
    ```go
    package main
    
    import (
        "bufio"
        "errors"
        "fmt"
        "strconv"
        "strings"
    )
    
    func MultipleFromString(str string) (int, error) {
        // Scanner -> io.Reader -> buifo.NewScanner(str) X
        scanner := bufio.NewScanner(strings.NewReader(str))
        scanner.Split(bufio.ScanWords)
    
        pos := 0
        a, n, err := readNextInt(scanner)
        if err != nil {
            return 0, fmt.Errorf("Failed to readNextInt(), pos:%d, err: \n    %w", pos, err)
        }
    
        pos += n + 1
        b, n, err := readNextInt(scanner)
        if err != nil {
            return 0, fmt.Errorf("Failed to readNextInt(), pos:%d, err: \n    %w", pos, err)
        }
    
        return a * b, nil
    }
    
    func readNextInt(scanner *bufio.Scanner) (int, int, error) {
        if !scanner.Scan() {
            return 0, 0, fmt.Errorf("Failed to scan")
        }
        word := scanner.Text()
    
        // 여기에서 첫번째 에러 : "abc" -> 에러
        number, err := strconv.Atoi(word)
        if err != nil {
            return 0, 0, fmt.Errorf("Failed to convert word to int, word:%s, err: \n        %w", word, err)
        }
        return number, len(word), nil
    }
    
    func readEq(eq string) {
        rst, err := MultipleFromString(eq)
        if err == nil {
            fmt.Println(rst)
        } else {
            fmt.Println(err)
            var numError *strconv.NumError
            if errors.As(err, &numError) {
                fmt.Println("NumberError -> ", numError)
            }
        }
    }
    
    func main() {
        readEq("123 abc")
    }
    
    /*출력
    Failed to readNextInt(), pos:4, err: 
        Failed to convert word to int, word:abc, err: 
            strconv.Atoi: parsing "abc": invalid syntax
    NumberError ->  strconv.Atoi: parsing "abc": invalid syntax
    */
    ```
    

# 4\. 패닉

-   처리하기 힘든 에러를 만났을 때 프로그램을 조기 종료하는 방법, 빠르게 종료시켜 오류를 해결
-   어디서 에러가 났는지 명확히 보여줌
-   모든 타입 사용 가능
-   충돌은 콜스택 역순으로 전파, 역순으로 올라가면서 복구확인
-   panic - defer - recover, recover (패닉객체를반환)

```go
package main

import (
    "fmt"
)

func f() {
    fmt.Println("f() function start")
    defer func() {
        if r := recover(); r != nil {
            fmt.Println("panic recover -> ", r)
        }
    }()

    g()
    fmt.Println("f() function terminated")
}

func g() {
    fmt.Printf("%d\n", h(9, 0))
}

func h(a, b int) int {
    if b == 0 {
        panic("b is not 0")
    }
    return a / b
}

func main() {
    f()
    fmt.Println("not terminated")
}


/*
---> defer 있을 때
f() function start
panic recover ->  b is not 0
not terminated

---> defer가 없으면 panic에서 종료됨
f() function start
panic: b is not 0

goroutine 1 [running]:
main.h(0x9, 0x0, 0x0)
    /Users/home/go/goProject/goLang/go1.go:25 +0x85
main.g()
    /Users/home/go/goProject/goLang/go1.go:20 +0x45
main.f()
    /Users/home/go/goProject/goLang/go1.go:15 +0x96
main.main()
    /Users/home/go/goProject/goLang/go1.go:31 +0x26
*/
```

# 5\. Go는 SHE를 지원하지 않음

-   SHE : Structured Error Handling, 구조화된 에러 처리
-   try, catch, finally, exception
-   성능 문제, 에러 처리